Workbook

Sheet 0.제공테이블
C3: 금융기관 - 데이터 제공 레이아웃
F5: 문서버전 | G5: : | H5: 4.0
F6: 작성일자 | G6: : | H6: 2024년 8월
F7: 수정일자 | G7: : | H7: 2024년 12월 9일
C9: NO | D9: Category | E9: Description | F9: Reference
C10: 1 | D10: ='1.월별_매출정보'!B2 -> 월별_매출정보 | E10: 적격증빙 기준 월단위 부가세 매출정보 제공 | F10: 기준년월
F11: 사업자등록번호
F12: 법인등록번호
F13: 공급시기
F14: 매출처사업자번호
F15: 매출처명
F16: 공급가액
F17: 부가세
F18: 매출유형
F19: 공급건수
F20: 취소건수
F21: 취소금액
F22: 총공급가액
... F24: 거래비중
C27: 2 | D27: =[1]월별_매입정보!J1 -> 월별_매입정보 | E27: 적격증빙 기준 월단위 부가세 매입정보 제공 | F27: 기준년월
F28: 사업자등록번호
F29: 법인등록번호
F30: 공급받는시기
F31: 매입처사업자번호
F32: 매입처명
F33: 공급가액
F34: 부가세
F35: 매입유형
F36: 공급건수
F37: 취소건수
F38: 취소금액
F39: 총공급가액
... F41: 거래비중
C44: 3 | D44: =[1]거래처별매출채권정보!J1 -> 거래처별매출채권정보 | E44: 월단위 매출처에 대한 발생액-회수액 정보 제공 | F44: 기준년월
F45: 사업자등록번호
F46: 법인등록번호
F47: 매출처사업자번호
F48: 매출처명
F49: 발생(회수)월
F50: 매출채권발생액
...

Sheet 1.월별_매출정보
A1: 영문테이블명 | B1: FTA_MTH_SALES | I1: 목차 | J1: =MID(CELL("filename",G6),FIND("]",CELL("filename",G6))+1,255) -> #VALUE!
A2: 한글테이블명 | B2: 월별_매출정보
A4: 영문컬럼명 | B4: 한글컬럼명 | C4: 데이터타입 | D4: BIZ컬럼설명 | E4: 비고 | F4: 기간 | G4: PK
A5: DW_BAS_NYYMM | B5: 기준년월 | C5: CHAR(6) | D5: YYYYMM, 연도 4자리+월 2자리 | E5: 기준년월에 대해 전전월 데이터를 제공함 | F5: 최초 제공 후 13개월 변동을 체크하여 매월 업데이트 함 | G5: ○
A6: NO_BIZ | B6: 사업자등록번호 | C6: CHAR(10) | D6: 대상사업자 사업자번호 10자리 | E6: CASE WHEN SUBSTR(no_biz, 4, 2) BETWEEN '81' AND '88' THEN '법인' ELSE '개인' END AS no_biz | G6: ○
A7: NO_CORPOR | B7: 법인등록번호 | C7: varchar(13) | D7: 법인만 수록, 개인사업자는 숫자9 13개, 나머지 공란 | E7: CASE WHEN NO_BIZ IN ('법인사업자') THEN NO_CORPOR IN ('법인번호') NO_BIZ IN ('개인사업자') THEN NO_CORPOR IN ('9999999999999') --숫자 9 13개 입력 ELSE NULL END AS NO_CORPOR
A8: DM_DATA | B8: 공급시기 | C8: char(6) | D8: YYYYMM, 연도 4자리+월 2자리, 기준년월(DW_BAS_NYYMM)로부터 최근 3개년 정보 제공 | F8: 월 | G8: ○
A9: NO_BISOCIAL | B9: 매출처사업자번호 | C9: varchar(200) | D9: 대상 사업자(NO_BIZ)가 판매를 진행한 매출처의 사업자등록번호 | E9: (ASIS) 사업자번호 미입력 시 주민번호 앞자리 제공 사업자,주민번호 미입력 시 거래처번호(5자리)제공 >거래처번호: 거래처코드 5자리 >no_biz별 00101~97999까지 입력가능함 (TOBE) 사업자번호 NULL인 경우 1) 주민번호 입력분 : (00000000000)숫자 0 10개 2) 그 외 : (9999999999) 숫자 9 10개 | F9: 월 | G9: ○
A10: NM_TRADE | B10: 매출처명 | C10: varchar(300) | D10: NO_BISOCIAL에 대해 사용자가 입력한 매출처명 | E10: (ASIS) 거래처등록-거래처명 표기 (TOBE) 사업자번호 NULL인 경우 1) 주민번호 입력분 : (00000000000)숫자 0 10개 : 개인으로 표기 2) 그 외 : (9999999999) 숫자 9 10개 : 기타로 표기 | F10: 월
A11: MN_MNAM | B11: 공급가액 | C11: numeric(20,2) | D11: 대상 사업자(NO_BIZ)가 공급시기(DM_DATA)에 특정 매출처(NO_BISOCIAL)를 대상으로 매출상세(TY_MTH2)별로 제공한 공급가액의 총액 | E11: 총 매출 거래에 대한 거래처별 공급가액의 합계 ※DM_DATA 기준 발생건을 모두 취소한 경우 금액=0 | F11: 월
A12: MN_VAT | B12: 부가세 | C12: numeric(20,2) | D12: 대상 사업자(NO_BIZ)가 공급시기(DM_DATA)에 특정 매출처(NO_BISOCIAL)를 대상으로 매출상세(TY_MTH2)별로 제공한 부가세의 총액 | F12: 월
A13: TY_MTH2 | B13: 매출유형 | C13: CHAR(2) | D13: 하단 유형번호 11~25번 수록 | E13: 유형 외 다른 값 수록 시, 99로 변경 | F13: 월 | G13: ○
A14: CT_MNAM | B14: 공급건수 | C14: INTEGER | D14: 대상 사업자(NO_BIZ)가 공급시기(DM_DATA)에 특정 매출처(NO_BISOCIAL)를 대상으로 매출상세(TY_MTH2)별로 제공한 총공급건수 | E14: MN_MNAM<>0인 총 거래건수 ※DM_DATA 기준 발생 및 취소 건을 모두 집계함 | F14: 월
A15: CT_MNAM_M | B15: 취소건수 | C15: INTEGER | D15: 대상 사업자(NO_BIZ)가 공급시기(DM_DATA)에 특정 매출처(NO_BISOCIAL)를 대상으로 매출상세(TY_MTH2)별로 취소한 건수 | E15: MN_MNAM<0인 거래건수 ※DM_DATA 취소 건을 모두 집계함 ※취소 : 수정T/I발생 사유(반품,계약해지,착오발급 등) | F15: 월
A16: MN_MNAM_M | B16: 취소금액 | C16: numeric(20,2) | D16: 대상 사업자(NO_BIZ)가 공급시기(DM_DATA)에 특정 매출처(NO_BISOCIAL)를 대상으로 매출상세(TY_MTH2)별로 취소한 금액 | E16: MN_MNAM<0인 거래건에 대한 금액 합계 | F16: 월
A17: TOT_MN_MNAM | B17: 총공급가액 | C17: numeric(20,2) | D17: 대상 사업자(NO_BIZ)가 공급시기(DM_DATA)에 전체 매출처(NO_BISOCIAL)를 대상으로 공급한 총액 | E17: 총 매출 거래에 대한 공급가액의 합계 | F17: 월
A18: TOT_MN_MNAM_M | B18: 총취소금액 | C18: numeric(20,2) | D18: 대상 사업자(NO_BIZ)가 공급시기(DM_DATA)에 전체 매출처(NO_BISOCIAL)를 대상으로 취소한 금액 | E18: MN_MNAM<0인 거래건에 대한 총 금액 합계 | F18: 월
A19: TRAN_RATE | B19: 거래비중 | C19: numeric(20,2) | D19: 분자: 거래처별 매출액(MN_MNAM) 분모: 총 매출액(TOT_MN_MNAM) | E19: CASE WHEN 분자<0 THEN TRAN_RATE=-99999 WHEN 분모<=0 THEN TRAN_RATE=99999 (테크핀 기준 적용) ELSE 분자/분모 | F19: 월

Sheet 2.월별_매입정보
A1: 영문테이블명 | B1: FTA_MTH_BUY | I1: 목차 | J1: =MID(CELL("filename",I3),FIND("]",CELL("filename",I3))+1,255) -> #VALUE!
A2: 한글테이블명 | B2: 월별_매입정보
A4: 영문컬럼명 | B4: 한글컬럼명 | C4: 데이터타입 | D4: BIZ컬럼설명 | E4: 비고 | F4: 기간 | G4: PK
A5: DW_BAS_NYYMM | B5: 기준년월 | C5: CHAR(6) | D5: YYYYMM, 연도 4자리+월 2자리 | E5: 기준년월에 대해 전전월 데이터를 제공함 | F5: 최초 제공 후 13개월 변동을 체크하여 매월 업데이트 함 | G5: ○
A6: NO_BIZ | B6: 사업자등록번호 | C6: CHAR(10) | D6: 대상사업자 사업자번호 10자리 | E6: CASE WHEN SUBSTR(no_biz, 4, 2) BETWEEN '81' AND '88' THEN '법인사업자' ELSE '개인사업자' END AS no_biz | G6: ○
A7: NO_CORPOR | B7: 법인등록번호 | C7: varchar(13) | D7: 법인만 수록, 개인사업자는 숫자9 13개, 나머지 공란 | E7: CASE WHEN NO_BIZ IN ('법인사업자') THEN NO_CORPOR IN ('법인번호') NO_BIZ IN ('개인사업자') THEN NO_CORPOR IN ('9999999999999') --숫자 9 13개 입력 ELSE NULL END AS NO_CORPOR
A8: DM_DATA | B8: 공급받는시기 | C8: char(6) | D8: YYYYMM, 연도 4자리+월 2자리, 기준년월(DW_BAS_NYYMM)로부터 최근 3개년 정보 제공 | F8: 월 | G8: ○
A9: NO_BISOCIAL | B9: 매입처사업자번호 | C9: varchar(200) | D9: 대상 사업자(NO_BIZ)가 구매를 진행한 매입처의 사업자등록번호 | E9: (ASIS) 사업자번호 미입력 시 주민번호 앞자리 제공 사업자,주민번호 미입력 시 거래처번호(5자리)제공 >거래처번호: 거래처코드 5자리 >no_biz별 00101~97999까지 입력가능함 (TOBE) 사업자번호 NULL인 경우 1) 주민번호 입력분 : (00000000000)숫자 0 10개 2) 그 외 : (9999999999) 숫자 9 10개 | F9: 월 | G9: ○
A10: NM_TRADE | B10: 매입처명 | C10: varchar(300) | D10: NO_BISOCIAL에 대해 사용자가 입력한 매입처명 | E10: (ASIS) 거래처등록-거래처명 표기 (TOBE) 사업자번호 NULL인 경우 1) 주민번호 입력분 : (00000000000)숫자 0 10개 : 개인으로 표기 2) 그 외 : (9999999999) 숫자 9 10개 : 기타로 표기 | F10: 월
A11: MN_MNAM | B11: 공급가액 | C11: numeric(20,2) | D11: 대상 사업자(NO_BIZ)가 공급받는시기(DM_DATA)에 특정 매입처(NO_BISOCIAL)를 대상으로 매입상세(TY_MTH2)별로 제공받은 공급가액의 총액 | E11: 총 매입 거래에 대한 공급가액의 합계 ※DM_DATA 기준 발생건을 모두 취소한 경우 금액=0 | F11: 월
A12: MN_VAT | B12: 부가세 | C12: numeric(20,2) | D12: 대상 사업자(NO_BIZ)가 공급받는시기(DM_DATA)에 특정 매입처(NO_BISOCIAL)를 대상으로 매입상세(TY_MTH2)별로 제공받은 부가세의 총액 | F12: 월
A13: TY_MTH2 | B13: 매입유형 | C13: CHAR(2) | D13: 하단 유형번호 51~64번 수록 | E13: 유형 외 다른 값 수록 시, 99로 변경 | F13: 월 | G13: ○
A14: CT_MNAM | B14: 공급건수 | C14: INTEGER | D14: 대상 사업자(NO_BIZ)가 공급받는시기(DM_DATA)에 특정 매입처(NO_BISOCIAL)를 대상으로 매입상세(TY_MTH2)별로 제공받는 총공급건수 | E14: MN_MNAM<>0인 총 거래건수 ※DM_DATA 기준 발생 및 취소 건을 모두 집계함 | F14: 월
A15: CT_MNAM_M | B15: 취소건수 | C15: INTEGER | D15: 대상 사업자(NO_BIZ)가 공급받는시기(DM_DATA)에 특정 매입처(NO_BISOCIAL)를 대상으로 매입상세(TY_MTH2)별로 취소한 건수 | E15: MN_MNAM<0인 거래건수 ※DM_DATA 취소 건을 모두 집계함 ※취소 : 수정T/I발생 사유(반품,계약해지,착오발급 등) | F15: 월
A16: MN_MNAM_M | B16: 취소금액 | C16: numeric(20,2) | D16: 대상 사업자(NO_BIZ)가 공급받는시기(DM_DATA)에 특정 매입처(NO_BISOCIAL)를 대상으로 매입상세(TY_MTH2)별로 취소한 금액 | E16: MN_MNAM<0인 거래건에 대한 금액 합계 | F16: 월
A17: TOT_MN_MNAM | B17: 총공급가액 | C17: numeric(20,2) | D17: 대상 사업자(NO_BIZ)가 공급받는시기(DM_DATA)에 전체 매입처(NO_BISOCIAL)를 대상으로 제공받은 공급가액 총액 | E17: 총 매입 거래에 대한 공급가액의 합계 | F17: 월
A18: TOT_MN_MNAM_M | B18: 총취소금액 | C18: numeric(20,2) | D18: 대상 사업자(NO_BIZ)가 공급받는시기(DM_DATA)에 전체 매입처(NO_BISOCIAL)를 대상으로 취소한 금액 | E18: MN_MNAM<0인 거래건에 대한 총 금액 합계 | F18: 월
A19: TRAN_RATE | B19: 거래비중 | C19: numeric(20,2) | D19: 분자: 거래처별 매입액(MN_MNAM) 분모: 총 매입액(TOT_MN_MNAM) | E19: CASE WHEN 분자<0 THEN TRAN_RATE=-99999 WHEN 분모<=0 THEN TRAN_RATE=99999 (테크핀 기준 적용) ELSE 분자/분모 | F19: 월

Sheet 3.거래처별매출채권정보
A1: 영문테이블명 | B1: FTA_TRADEAR | I1: 목차 | J1: =MID(CELL("filename",I4),FIND("]",CELL("filename",I4))+1,255) -> #VALUE!
A2: 한글테이블명 | B2: 거래처별매출채권정보
A4: 영문컬럼명 | B4: 한글컬럼명 | C4: 데이터타입 | D4: BIZ컬럼설명 | E4: 비고 | F4: 기간 | G4: PK
A5: DW_BAS_NYYMM | B5: 기준년월 | C5: CHAR(6) | D5: YYYYMM, 연도 4자리+월 2자리 | E5: 기준년월에 대해 전전월 데이터를 제공함 | F5: 최초 제공 후 13개월 변동을 체크하여 매월 업데이트 함 | G5: ○
A6: NO_BIZ | B6: 사업자등록번호 | C6: CHAR(10) | D6: 대상사업자 사업자번호 10자리 | E6: CASE WHEN SUBSTR(no_biz, 4, 2) BETWEEN '81' AND '88' THEN '법인사업자' ELSE '개인사업자' END AS no_biz | G6: ○
A7: NO_CORPOR | B7: 법인등록번호 | C7: varchar(13) | D7: 법인만 수록, 개인사업자는 숫자9 13개, 나머지 공란 | E7: CASE WHEN NO_BIZ IN ('법인사업자') THEN NO_CORPOR IN ('법인번호') NO_BIZ IN ('개인사업자') THEN NO_CORPOR IN ('9999999999999') --숫자 9 13개 입력 ELSE NULL END AS NO_CORPOR
A8: NO_BISOCIAL | B8: 매출처사업자번호 | C8: varchar(200) | D8: 대상사업자(NO_BIZ)가 판매를 진행한 매출처의 사업자등록번호 | E8: (ASIS) 사업자번호 미입력 시 주민번호 앞자리 제공 사업자,주민번호 미입력 시 거래처번호(5자리)제공 >거래처번호: 거래처코드 5자리 >no_biz별 00101~97999까지 입력가능함 (TOBE) 사업자번호 NULL인 경우 1) 주민번호 입력분 : (00000000000)숫자 0 10개 2) 그 외 : (9999999999) 숫자 9 10개 | F8: 월 | G8: ○
A9: NM_TRADE | B9: 매출처명 | C9: varchar(300) | D9: NO_BISOCIAL에 대해 사용자가 입력한 매출처명 | E9: (ASIS) 거래처등록-거래처명 표기 (TOBE) 사업자번호 NULL인 경우 1) 주민번호 입력분 : (00000000000)숫자 0 10개 : 개인으로 표기 2) 그 외 : (9999999999) 숫자 9 10개 : 기타로 표기 | F9: 월
A10: DM_DATA | B10: 발생(회수)월 | C10: char(6) | D10: YYYYMM, 연도 4자리+월 2자리, 기준년월(DW_BAS_NYYMM)로부터 최근12개월 동안 매출채권의 발생 또는 회수가 발생한 월 | F10: 월 | G10: ○
A11: MN_AR | B11: 매출채권발생액 | C11: numeric(20,2) | D11: 대상사업자(NO_BIZ)가 발생월(DM_DATA)에 특정 매출처(NO_BISOCIAL)를 대상으로 판매한 매출채권의 총액 | E11: 더존코드 기준 외상매출금, 받을어음, 공사미수금 3개를 매출채권으로 봄(미수금 포함여부 검토) | F11: 월
A12: MN_RCV | B12: 매출채권회수액 | C12: numeric(20,2) | D12: 대상사업자(NO_BIZ)가 회수월(DM_DATA)에 특정 매출처(NO_BISOCIAL)를 대상으로 회수한 매출채권의 총액 | F12: 월

Sheet 4.거래처별매입채무정보
A1: 영문테이블명 | B1: FTA_TRADEAP | I1: 목차 | J1: =MID(CELL("filename",I4),FIND("]",CELL("filename",I4))+1,255) -> #VALUE!
A2: 한글테이블명 | B2: 거래처별매입채무정보
A4: 영문컬럼명 | B4: 한글컬럼명 | C4: 데이터타입 | D4: BIZ컬럼설명 | E4: 비고 | F4: 기간 | G4: PK
A5: DW_BAS_NYYMM | B5: 기준년월 | C5: CHAR(6) | D5: YYYYMM, 연도 4자리+월 2자리 | E5: 기준년월에 대해 전전월 데이터를 제공함 | F5: 최초 제공 후 13개월 변동을 체크하여 매월 업데이트 함 | G5: ○
A6: NO_BIZ | B6: 사업자등록번호 | C6: CHAR(10) | D6: 대상사업자 사업자번호 10자리 | E6: CASE WHEN SUBSTR(no_biz, 4, 2) BETWEEN '81' AND '88' THEN '법인사업자' ELSE '개인사업자' END AS no_biz | G6: ○
A7: NO_CORPOR | B7: 법인등록번호 | C7: varchar(13) | D7: 법인만 수록, 개인사업자는 숫자9 13개, 나머지 공란 | E7: CASE WHEN NO_BIZ IN ('법인사업자') THEN NO_CORPOR IN ('법인번호') NO_BIZ IN ('개인사업자') THEN NO_CORPOR IN ('9999999999999') --숫자 9 13개 입력 ELSE NULL END AS NO_CORPOR
A8: NO_BISOCIAL | B8: 매입처사업자번호 | C8: varchar(10) | D8: 대상사업자(NO_BIZ)가 구매를 진행한 구매처의 사업자등록번호 | E8: (ASIS) 사업자번호 미입력 시 주민번호 앞자리 제공 사업자,주민번호 미입력 시 거래처번호(5자리)제공 >거래처번호: 거래처코드 5자리 >no_biz별 00101~97999까지 입력가능함 (TOBE) 사업자번호 NULL인 경우 1) 주민번호 입력분 : (00000000000)숫자 0 10개 2) 그 외 : (9999999999) 숫자 9 10개 | F8: 월 | G8: ○
A9: NM_TRADE | B9: 매입처명 | C9: varchar(300) | D9: NO_BISOCIAL에 대해 사용자가 입력한 매입처명 | E9: (ASIS) 거래처등록-거래처명 표기 (TOBE) 사업자번호 NULL인 경우 1) 주민번호 입력분 : (00000000000)숫자 0 10개 : 개인으로 표기 2) 그 외 : (9999999999) 숫자 9 10개 : 기타로 표기 | F9: 월
A10: DM_DATA | B10: 발생(지급)월 | C10: char(6) | D10: YYYYMM, 연도 4자리+월 2자리, 기준년월(DW_BAS_NYYMM)로부터 최근12개월 동안 매입채무의 발생 또는 지급이 발생한 월 | F10: 월 | G10: ○
A11: MN_AP | B11: 매입채무발생액 | C11: numeric(20,2) | D11: 대상사업자(NO_BIZ)가 발생월(DM_DATA)에 특정 매입처(NO_BISOCIAL)를 대상으로 구매한 매입채무의 총액 | E11: 더존코드 기준 외상매입금, 지급어음, 미지급금 3개를 매입채무로 봄 | F11: 월
A12: MN_PAY | B12: 매입채무지급액 | C12: numeric(20,2) | D12: 대상사업자(NO_BIZ)가 지급월(DM_DATA)에 특정 매입처(NO_BISOCIAL)를 대상으로 지급한 매입채무의 총액 | F12: 월

Sheet 5.거래처별매출채권회수기간
A1: 영문테이블명 | B1: FTA_DPAYR | I1: 목차 | J1: =MID(CELL("filename",I4),FIND("]",CELL("filename",I4))+1,255) -> #VALUE!
A2: 한글테이블명 | B2: 거래처별매출채권회수기간
A4: 영문컬럼명 | B4: 한글컬럼명 | C4: 데이터타입 | D4: BIZ컬럼설명 | E4: 비고 | F4: 기간 | G4: PK
A5: DW_BAS_NYYMM | B5: 기준년월 | C5: CHAR(6) | D5: YYYYMM, 연도 4자리+월 2자리 | E5: 기준년월에 대해 전전월 데이터를 제공함 | F5: 최초 제공 후 매월 업데이트 함 | G5: ○
A6: NO_BIZ | B6: 사업자등록번호 | C6: CHAR(10) | D6: 대상사업자 사업자번호 10자리 | E6: CASE WHEN SUBSTR(no_biz, 4, 2) BETWEEN '81' AND '88' THEN '법인사업자' ELSE '개인사업자' END AS no_biz | G6: ○
A7: NO_CORPOR | B7: 법인등록번호 | C7: varchar(13) | D7: 법인만 수록, 개인사업자는 숫자9 13개, 나머지 공란 | E7: CASE WHEN NO_BIZ IN ('법인사업자') THEN NO_CORPOR IN ('법인번호') NO_BIZ IN ('개인사업자') THEN NO_CORPOR IN ('9999999999999') --숫자 9 13개 입력 ELSE NULL END AS NO_CORPOR
A8: DM_ST | B8: 회수시작월 | C8: CHAR(6) | D8: 회수기간을 산정하기 위한 시작월 | E8: CT_TERM(기간구분)에 따라 회수기간을 계산하는 시작월 | F8: 월 | G8: ○
A9: DM_END | B9: 회수종료월 | C9: CHAR(6) | D9: 회수기간을 산정하기 위한 종료월 | E9: CT_TERM(기간구분)에 따라 회수기간을 계산하는 종료월 | F9: 월 | G9: ○
A10: NO_BISOCIAL | B10: 매출처사업자번호 | C10: varchar(200) | D10: 대상사업자(NO_BIZ)가 판매를 진행한 매출처의 사업자등록번호 | E10: (ASIS) 사업자번호 미입력 시 주민번호 앞자리 제공 사업자,주민번호 미입력 시 거래처번호(5자리)제공 >거래처번호: 거래처코드 5자리 >no_biz별 00101~97999까지 입력가능함 (TOBE) 사업자번호 NULL인 경우 1) 주민번호 입력분 : (00000000000)숫자 0 10개 2) 그 외 : (9999999999) 숫자 9 10개 | F10: 월 | G10: ○
A11: NM_TRADE | B11: 매출처명 | C11: varchar(300) | D11: NO_BISOCIAL에 대해 사용자가 입력한 매출처명 | E11: (ASIS) 거래처등록-거래처명 표기 (TOBE) 사업자번호 NULL인 경우 1) 주민번호 입력분 : (00000000000)숫자 0 10개 : 개인으로 표기 2) 그 외 : (9999999999) 숫자 9 10개 : 기타로 표기 | F11: 월
A12: DPAYR | B12: 회수기간 | C12: numeric(20,6) | D12: ①회수기준월(DM_DATA)로부터 직전 24개월(또는 그 이상)에 해당하는 매출채권 잔액을 계산하고 ②회수금액을 선입선출법으로 상계하여 ③매출채권 잔액보다 회수금액이 큰 기간을 회수기간(ex. 30.256175일 )으로 봄 | E12: 회수(지급)기간산출로직 시트 참조 | F12: 월
A13: RATE_PAYR | B13: 회수율 | C13: numeric(20,8) | D13: (분자)회수된 매출채권금액/ (분모)순발생매출채권 | F13: 월
A14: CD_TERM | B14: 기간구분 | C14: CHAR(1) | D14: 1: 최근 12개월 2: 직전 12개월 3: 최근 24개월 | E14: DM_DATA로부터 과거 24개월+@에 대한 거래내역에 대해서 12개월 단위로 구분한 (최근 12개월, 직전 12개월) 회수기간 및 회수율과 24개월 단위로 산정한 (최근 24개월) 회수기간 및 회수율을 제공함 기간산정기준 시트 참조 | F14: 월 | G14: ○
A15: MN_CAR | B15: 매출채권 회수금액 | C15: numeric(20.0) | D15: 매출채권 회수기간 = (분자)매출채권 가중평균 회수금액/ (분모)매출채권 회수금액 | E15: 회수기간 산출 근거가 되는 분모값 | F15: 월
A16: MN_WCAR | B16: 매출채권 가중평균 회수금액 | C16: numeric(20.0) | D16: 매출채권 회수기간 = (분자)매출채권 가중평균 회수금액/ (분모)매출채권 회수금액 | E16: 회수기간 산출 근거가 되는 분자값 | F16: 월

Sheet 6.거래처별매입채무지급기간
A1: 영문테이블명 | B1: FTA_DPAYP | I1: 목차 | J1: =MID(CELL("filename",I4),FIND("]",CELL("filename",I4))+1,255) -> #VALUE!
A2: 한글테이블명 | B2: 거래처별매입채무지급기간
A4: 영문컬럼명 | B4: 한글컬럼명 | C4: 데이터타입 | D4: BIZ컬럼설명 | E4: 비고 | F4: 기간 | G4: PK
A5: DW_BAS_NYYMM | B5: 기준년월 | C5: CHAR(6) | D5: YYYYMM, 연도 4자리+월 2자리 | E5: 기준년월에 대해 전전월 데이터를 제공함 | F5: 최초 제공 후 매월 업데이트 함 | G5: ○
A6: NO_BIZ | B6: 사업자등록번호 | C6: CHAR(10) | D6: 대상사업자 사업자번호 10자리 | E6: CASE WHEN SUBSTR(no_biz, 4, 2) BETWEEN '81' AND '88' THEN '법인사업자' ELSE '개인사업자' END AS no_biz | G6: ○
A7: NO_CORPOR | B7: 법인등록번호 | C7: varchar(13) | D7: 법인만 수록, 개인사업자는 숫자9 13개, 나머지 공란 | E7: CASE WHEN NO_BIZ IN ('법인사업자') THEN NO_CORPOR IN ('법인번호') NO_BIZ IN ('개인사업자') THEN NO_CORPOR IN ('9999999999999') --숫자 9 13개 입력 ELSE NULL END AS NO_CORPOR
A8: DM_ST | B8: 지급시작월 | C8: CHAR(6) | D8: 지급기간을 산정하기 위한 시작월 | E8: CT_TERM(기간구분)에 따라 지급기간을 계산하는 시작월 | F8: 월 | G8: ○
A9: DM_END | B9: 지급종료월 | C9: CHAR(6) | D9: 지급기간을 산정하기 위한 종료월 | E9: CT_TERM(기간구분)에 따라 지급기간을 계산하는 종료월 | F9: 월 | G9: ○
A10: NO_BISOCIAL | B10: 매입처사업자번호 | C10: varchar(200) | D10: 대상사업자(NO_BIZ)가 구매를 진행한 구매처의 사업자등록번호 | E10: (ASIS) 사업자번호 미입력 시 주민번호 앞자리 제공 사업자,주민번호 미입력 시 거래처번호(5자리)제공 >거래처번호: 거래처코드 5자리 >no_biz별 00101~97999까지 입력가능함 (TOBE) 사업자번호 NULL인 경우 1) 주민번호 입력분 : (00000000000)숫자 0 10개 2) 그 외 : (9999999999) 숫자 9 10개 | F10: 월 | G10: ○
A11: NM_TRADE | B11: 매입처명 | C11: varchar(300) | D11: NO_BISOCIAL에 대해 사용자가 입력한 매입처명 | E11: (ASIS) 거래처등록-거래처명 표기 (TOBE) 사업자번호 NULL인 경우 1) 주민번호 입력분 : (00000000000)숫자 0 10개 : 개인으로 표기 2) 그 외 : (9999999999) 숫자 9 10개 : 기타로 표기 | F11: 월
A12: DPAYP | B12: 지급기간 | C12: numeric(20,6) | D12: ①지급기준월(DM_DATA)로부터 직전 12개월(또는 그 이상)에 해당하는 매입채무 잔액을 계산하고 ②지급금액을 선입선출법으로 상계하여 ③매입채무 잔액보다 지급금액이 큰 기간을 지급기간(ex. 30.256175일 )으로 봄 | E12: 회수(지급)기간산출로직 시트 참조 | F12: 월
A13: RATE_PAYP | B13: 지급율 | C13: numeric(20,8) | D13: (분자)지급한 매입채무금액/ (분모)순발생매입채무 | F13: 월
A14: CD_TERM | B14: 기간구분 | C14: CHAR(1) | D14: 1: 최근 12개월 2: 직전 12개월 3: 최근 24개월 | E14: DM_DATA로부터 과거 24개월+@에 대한 거래내역에 대해서 12개월 단위로 구분한 (최근 12개월, 직전 12개월) 지급기간 및 지급율과 24개월 단위로 산정한 (최근 24개월) 지급기간 및 지급율을 제공함 | F14: 월 | G14: ○
A15: MN_PAP | B15: 매입채무 지급금액 | C15: numeric(20.0) | D15: 매입채무 지급기간 = (분자)매입채무 가중평균 지급금액/ (분모)매입채무 지급금액 | E15: 지급기간 산출 근거가 되는 분모값 | F15: 월
A16: MN_WPAP | B16: 매입채무 가중평균 지급금액 | C16: numeric(20.0) | D16: 매입채무 지급기간 = (분자)매입채무 가중평균 지급금액/ (분모)매입채무 지급금액 | E16: 지급기간 산출 근거가 되는 분자값 | F16: 월

Sheet 7.분기별_매출매입정보
A1: 영문테이블명 | B1: FTA_VAT_INFO | I1: 목차 | J1: =MID(CELL("filename",I4),FIND("]",CELL("filename",I4))+1,255) -> #VALUE!
A2: 한글테이블명 | B2: 분기별매출(매입)정보
A4: 영문컬럼명 | B4: 한글컬럼명 | C4: 데이터타입 | D4: BIZ컬럼설명 | E4: 비고 | F4: 기간 | G4: PK
A5: DW_BAS_NYYMM | B5: 기준년월 | C5: CHAR(6) | D5: YYYYMM, 연도 4자리+월 2자리 | E5: 기준년월에 대해 전전월 데이터를 제공함 | F5: 최초 제공 후 법인은 분기 단위로 개인사업자는 반기 단위로 변동을 체크하여 매월 제공함 | G5: ○
A6: NO_BIZ | B6: 사업자등록번호 | C6: CHAR(10) | D6: 대상사업자 사업자번호 10자리 | E6: CASE WHEN SUBSTR(no_biz, 4, 2) BETWEEN '81' AND '88' THEN '법인사업자' ELSE '개인사업자' END AS no_biz | G6: ○
A7: NO_CORPOR | B7: 법인등록번호 | C7: varchar(13) | D7: 법인만 수록, 개인사업자는 숫자9 13개, 나머지 공란 | E7: CASE WHEN NO_BIZ IN ('법인사업자') THEN NO_CORPOR IN ('법인번호') NO_BIZ IN ('개인사업자') THEN NO_CORPOR IN ('9999999999999') --숫자 9 13개 입력 ELSE NULL END AS NO_CORPOR
A8: YN_JIJUM | B8: 본지점구분 | C8: INTEGER | D8: CASE WHEN YN_JIJUM = 0 THEN '본점' WHEN YN_JIJUM = 1 AND substr(no_biz, 4, 2) IN ('81', '86', '87', '88') THEN '본점' WHEN YN_JIJUM = 1 THEN '지점' END AS 본지점구분 | E8: 2가지 방법이 있음 1. 회사등록>본지점여부로 판단(0.본점 1.지점) 2. 회사등록>사업자번호로 판단 단, 아래 조건은 명백히 본점으로 구분함 substr(no_biz,4,2) in ('81','86','87','88') | F8: 월
A9: NO_BISOCIAL | B9: 거래처사업자번호 | C9: varchar(200) | D9: 대상 사업자(NO_BIZ)가 판매(구매)를 진행한 매출(매입)처의 사업자등록번호 | E9: (ASIS) 사업자번호 미입력 시 주민번호 앞자리 제공 사업자,주민번호 미입력 시 거래처번호(5자리)제공 >거래처번호: 거래처코드 5자리 >no_biz별 00101~97999까지 입력가능함 (TOBE) 사업자번호 NULL인 경우 1) 주민번호 입력분 : (00000000000)숫자 0 10개 2) 그 외 : (9999999999) 숫자 9 10개 | F9: 월 | G9: ○
A10: NM_TRADE | B10: 거래처업체명 | C10: varchar(300) | D10: NO_BISOCIAL에 대해 사용자가 입력한 매출(매입)처명 | E10: (ASIS) 거래처등록-거래처명 표기 (TOBE) 사업자번호 NULL인 경우 1) 주민번호 입력분 : (00000000000)숫자 0 10개 : 개인으로 표기 2) 그 외 : (9999999999) 숫자 9 10개 : 기타로 표기 | F10: 월
A11: TY_MTH | B11: 매입매출구분 | C11: CHAR(1) | D11: 1 : 매출 2: 매입 | E11: 1,2만 수록함 | F11: 월 | G11: ○
A12: TY_MTH2 | B12: 매출매입유형 | C12: CHAR(2) | D12: 하단 유형번호 11~25번 수록 하단 유형번호 51~64번 수록 | E12: 유형 외 다른 값 수록 시, 99로 변경 | F12: 월 | G12: ○
A13: YYYY | B13: 기준년도 | C13: CHAR(4) | D13: SUBSTR(DM_DATA,1,4) | F13: 월 | G13: ○
A14: BAS_NQ | B14: 분기구분 | C14: CHAR(1) | D14: CASE WHEN SUBSTR(DM_DATA, 5, 2) BETWEEN '01' AND '03' THEN '1' WHEN SUBSTR(DM_DATA, 5, 2) BETWEEN '04' AND '06' THEN '2' WHEN SUBSTR(DM_DATA, 5, 2) BETWEEN '07' AND '09' THEN '3' WHEN SUBSTR(DM_DATA, 5, 2) BETWEEN '10' AND '12' THEN '4' WHEN SUBSTR(DM_DATA, 5, 2) BETWEEN '01' AND '06' THEN '5' WHEN SUBSTR(DM_DATA, 5, 2) BETWEEN '07' AND '12' THEN '6' END AS BAS_NQ CASE WHEN SUBSTR(NO_BIZ, 4, 2) BETWEEN '01' AND '79' THEN '1' -- 개인 WHEN SUBSTR(NO_BIZ, 4, 2) BETWEEN '90' AND '99' THEN '1' -- 개인 ELSE '2' -- 법인 END AS YN_PRIVATE | E14: 중간법인(12월말 법인이 아닌경우)이라도 1~3월/4~6월/7~9월/10~12월에 대한 매출(매입)내역을 분기별로 신고하는 것이 원칙임 ----------------------------------------------------- 법인 : 분기별 신고 개인 : 반기별 신고 ----------------------------------------------------- 사업자번호 기준 개인,법인 구분 법인인 경우 BAS_NQ IN ('1','2','3','4') 개인인 경우 BAS_NQ IN ('5','6') | F14: 월 | G14: ○
A15: TRAN_RATE | B15: 거래비중 | C15: numeric(20,2) | D15: 분자: 거래처별분기매입/매출액 분모: 분기총매입/매출액 | E15: CASE WHEN 분자<0 THEN TRAN_RATE=-99999 WHEN 분모<=0 THEN TRAN_RATE=99999 (테크핀 기준 적용) ELSE 분자/분모 | F15: 월
A16: TRAN_AMT | B16: 분기매입/매출액 | C16: numeric(20,2) | D16: NO_BIZ가 법인인 경우 거래처별 분기매입/매출정보 제공 개인인 경우 거래처별 반기매입/매출정보 제공 | E16: YN_PRIVATE IN (1,2) 법인인 경우 BAS_NQ IN ('1','2','3','4') and YN_PRIVATE = 2 개인인 경우 BAS_NQ IN ('5','6') and YN_PRIVATE = 1 | F16: 월
A17: TOT_TRAN_AMT | B17: 분기총매입/매출액 | C17: numeric(20,2) | D17: NO_BIZ가 법인인 경우 전체거래처에대한 분기매입/매출정보 제공 개인인 경우 전체거래처에 대한 반기매입/매출정보 제공 | F17: 월
A18: DA_ACCBEGIN | B18: 과세기간시작일자 | C18: CHAR(8) | D18: YYYYMMDD 월단위 전표기준으로 제공하므로, 법인은 3개월단위 개인은 6개월단위 정보를 제공함 | E18: >MMDD 정의 1분기 시작월일: 0101 고정 2분기 시작월일: 0401 고정 3분기 시작월일: 0701 고정 4분기 시작월일: 1001 고정 | F18: 월
A19: DA_ACCEND | B19: 과세기간종료일자 | C19: CHAR(8) | D19: YYYYMMDD 월단위 전표기준으로 제공하므로, 법인은 3개월단위 개인은 6개월단위 정보를 제공함 | E19: 휴폐업API조회되는 경우 또는 DA_END(폐업일)입력 법인의 경우 --------------------------------------------------------------- 1분기 종료월일: 0331 또는 폐업일 2분기 종료월일: 0630 또는 폐업일 3분기 종료월일: 0930 또는 폐업일 4분기 종료월일: 1231 또는 폐업일 | F19: 월
A20: CT_MNAM | B20: 분기공급건수 | C20: INTEGER | D20: 대상 사업자(NO_BIZ)가 공급시기(DM_DATA)에 특정 매출(매입)처(NO_BISOCIAL)를 대상으로 제공한 총공급건수 | E20: MN_MNAM<>0인 총 거래건수 ※DM_DATA 기준 발생 및 취소 건을 모두 집계함 >SUM(CT_MNAM) GROUP BY BAS_NQ,NO_BISOCIAL | F20: 월
A21: CT_MNAM_M | B21: 분기취소건수 | C21: INTEGER | D21: 대상 사업자(NO_BIZ)가 공급시기(DM_DATA)에 특정 매출(매입)처(NO_BISOCIAL)를 대상으로 취소한 건수 | E21: MN_MNAM<0인 거래건수 ※DM_DATA 취소 건을 모두 집계함 ※취소 : 수정T/I발생 사유(반품,계약채지,착오발급 등) >SUM(CT_MNAM_M) GROUP BY BAS_NQ,NO_BISOCIAL | F21: 월
A22: MN_MNAM_M | B22: 분기취소금액 | C22: numeric(20,2) | D22: 대상 사업자(NO_BIZ)가 공급시기(DM_DATA)에 특정 매출(매입)처 (NO_BISOCIAL)를 대상으로 취소한 금액 | E22: MN_MNAM<0인 거래건에 대한 금액 합계 >>SUM(MN_MNAM_M) GROUP BY BAS_NQ,NO_BISOCIAL | F22: 월
A23: TOT_MN_MNAM_M | B23: 분기총취소금액 | C23: numeric(20,2) | D23: 대상 사업자(NO_BIZ)가 공급시기(DM_DATA)에 전체 매출(매입)처 (NO_BISOCIAL)를 대상으로 취소한 금액 | E23: MN_MNAM<0인 거래건에 대한 금액 합계 >>SUM(MN_MNAM_M) GROUP BY BAS_NQ, NO_BIZ | F23: 월

Sheet 매출상세
A1: 유형 | B1: 거래증빙 | C1: 입력내용 | D1: 부가가치세 | F1: 목차
A2: 11.과세 | B2: 세금계산서 | C2: (전자)세금계산서 발급에 의한 매출 거래인 경우 | D2: 0.1
A3: 12.영세 | B3: 세금계산서 | C3: 내국신용장, 구매승인서 등 영세율(전자)세금계산서 발급에 의한 매출 거래인 경우 | D3: 0
A4: 13.면세 | B4: 계산서 | C4: 면세사업자가 발급하거나 면세품목을 거래하고 계산서에 의한 매출 거래인 경우 | D4: 해당없음
A5: 14.건별 | B5: 영수증 | C5: 세금계산서 및 현금영수증이 발급되지 않은 소매매출, 간주공급 등의 거래인 경우 | D5: 0.1
A6: 15.종합 | B6: 영수증 (간이과세의 경우) | C6: 세금계산서 및 현금영수증이 발급되지 않은 과세매출 거래인 경우 | D6: 0.1
C7: “14.건별”과의 차이는 공급가액란에 입력된 공급대가(VAT포함 금액)를 그대로 반영하여 공급가액과 부가가치세가 구분되지 않습니다.
A8: 16.수출 | C8: 외국환증명서, 수출면장 등에 의해 외국에 직접 수출하는 거래인 경우 | D8: 0
A9: 17.카과 | B9: 신용카드 | C9: 과세대상 거래로 신용카드매출전표 발급에 의한 거래인 경우 | D9: 0.1
A10: 18.카면 | B10: 신용카드 | C10: 면세대상 거래로 신용카드매출전표 발급에 의한 면세대상 매출 거래인 경우 | D10: 해당없음
A11: 19.카영 | B11: 신용카드 | C11: 영세율대상 거래로 신용카드매출전표 발급에 의한 매출 거래인 경우 | D11: 0
A12: 20.면건 | B12: 영수증 | C12: 계산서가 발급되지 않은 면세 매출 거래인 경우 | D12: 해당없음
A13: 21.전자 | B13: 전자화폐 | C13: 전자화폐 등 전자적 결제 수단을 이용한 매출 거래인 경우 | D13: 0.1
A14: 22.현과 | B14: 현금영수증 | C14: 과세대상 거래로 현금영수증 발급에 의한 매출 거래인 경우 | D14: 0.1
A15: 23.현면 | B15: 현금영수증 | C15: 면세대상 거래로 현금영수증 발급에 의한 면세대상 매출 거래인 경우 | D15: 해당없음
A16: 24.현영 | B16: 현금영수증 | C16: 영세율대상 거래로 현금영수증 발급에 의한 매출 거래인 경우 | D16: 0
A17: 25.매세 | B17: 세금계산서 | C17: 매입자발행세금계산서에 의한 매출 거래인 경우 | D17: 0.1

Sheet 참고

Sheet 매입상세
A1: 유형 | B1: 거래증빙 | C1: 입력내용 | D1: 부가가치세 | F1: 목차
A2: 51.과세 | B2: 세금계산서 | C2: (전자)세금계산서 수취에 의한 매입 거래인 경우 | D2: 0.1
A3: 52.영세 | B3: 세금계산서 | C3: 내국신용장, 구매승인서 등 영세율(전자)세금계산서 수취에 의한 매입 거래인 경우 | D3: 0
A4: 53.면세 | B4: 계산서 | C4: 면세사업자가 발급하거나 면세품목을 거래하고 계산서에 의한 매입 거래인 경우 | D4: 해당없음
A5: 54.불공 | B5: 세금계산서 | C5: (전자)세금계산서를 수취하였으나 부가가치세법에서 정하는 불공제 사유에 해당하는 매입 거래인 경우 | D5: 0.1
A6: 55.수입 | B6: 세금계산서 | C6: 세관장이 발급하는 수입세금계산서를 수취한 매입 거래인 경우 | D6: 0
A7: 56.금전 | B7: 영수증 | C7: 금전등록기 영수증에 의한 매입 거래인 경우 | D7: 0.1
A8: 57.카과 | B8: 신용카드 | C8: 과세대상 거래로 신용카드매출전표 수취에 의한 매입 거래인 경우 | D8: 0.1
A9: 58.카면 | B9: 신용카드 | C9: 면세대상 거래로 신용카드매출전표 수취에 의한 면세대상 매입 거래인 경우 | D9: 해당없음
A10: 59.카영 | B10: 신용카드 | C10: 영세율대상 거래로 신용카드매출전표 수취에 의한 매입 거래인 경우 | D10: 0
A11: 60.면건 | B11: 영수증 | C11: 계산서가 발급되지 않은 면세 매입 거래인 경우 | D11: 해당없음
A12: 61.현과 | B12: 현금영수증 | C12: 과세대상 거래로 현금영수증 수취에 의한 매입 거래인 경우 | D12: 0.1
A13: 62.현면 | B13: 현금영수증 | C13: 면세대상 거래로 현금영수증 수취에 의한 면세대상 매입 거래인 경우 | D13: 해당없음
A14: 63.복지 | B14: 복지카드 | C14: 과세대상 거래로 복지카드 수취에 의한 매입 거래인 경우 | D14: 0.1
A15: 64.매세 | B15: 세금계산서 | C15: 매입자발행세금계산서에 의한 매입 거래인 경우 | D15: 0.1

Sheet 기간산정기준
L1: 목차
B23: A거래처에 대해서 기준월(24년 3월)로부터 최근 24개월에 대한 회수내역을 기반으로 회수기간을 계산한다.
B24: 1. 24년 3월에 대한 직전 24개월은 22년 4월이므로 22년 4월의 매출채권 잔액을 계산한다.
B25: 2. 22년 4월의 매출채권에는 21년도에서 이월된 잔액(미회수채권)과 22년 1월~3월까지 발생된 금액을 포함한다.
B26: 3. 22년도 1월부터 회수된 금액은 미회수채권에서 먼저 차감하고 해당 내역은 회수기간에 포함하지 않는다.

Sheet 회수(지급)기간산출로직
K1: 목차
A2: 1. 거래처별 회수(지급)기간은 기준월로부터 24개월+@ 전까지 기간 단위로 설정함
A3: 2. 예를 들어, 기준월이 2024년 3월인 경우 24개월 전인 2022년 4월이 아닌, 회계기수의 시작인 2022년 1월 1일 까지를 기간 단위로 봄
A4: (이유, 2022년 4월 이전에 발생된 채권이 2022년 4월 이후에 회수될 수도 있으므로)
A5: 3. 거래처별로 발생된 매출채권에 대한 (매출채권이 차변에 입력됨) 회수는 (매출채권이 대변에 분개됨) 먼저 발생된 금액이 먼저 회수된다고 가정함 (선입선출법)
A11: 4. 회수기간은 가중평균 회수금액(회수금액 * 회수기간) 을 회수금액으로 나누어 계산함
A12: 5. 예시 : A회사와 b거래처 간의 회수기간은 아래의 과정대로 계산됨
A14: b거래처 | B14: 회수기간 (단위,일) | C14: 회수금액 | D14: 가중평균 회수금액
C15: 분모 | D15: 분자
A16: 최근12개월 | B16: =D16/C16 -> 129.8 | C16: =I49+I50+I51+I53+I54+I56 -> 5000000 | D16: =L49+L50+L51+L53+L54+L56 -> 649000000
A17: 직전12개월 | B17: =D17/C17 -> 162.11765 | C17: =I37+I38+I39+I41+I42+I45+I46 -> 5100000 | D17: =L37+L38+L39+L41+L42+L45+L46 -> 826800000
A18: 직전24개월 | B18: =D18/C18 -> 146.11881 | C18: =I37+I38+I39+I41+I42+I45+I46+I49+I50+I51+I53+I54+I56 -> 10100000 | D18: =L37+L38+L39+L41+L42+L45+L46+L49+L50+L51+L53+L54+L56 -> 1475800000
A23: 발생키 | B23: 발생일자 | C23: 발생 거래처 | D23: 기초금액 | E23: 발생금액 | F23: 회수키 | G23: 회수일자 | H23: 회수 거래처 | I23: 회수금액 | J23: 회수잔액 | K23: 회수기간 | L23: 가중평균 회수금액
A24: 1 | B24: 44562 | C24: b | D24: 1000000
F25: 1 | G25: 44590 | H25: b | I25: 500000 | J25: =D24-I25 -> 500000 | K25: 미산정
A26: 2 | B26: 44620 | C26: b | E26: 2000000
F27: 1 | G27: 44651 | H27: b | I27: 500000 | J27: =J25-I27 -> 0 | K27: 미산정
A28: 3 | B28: 44650 | C28: b | E28: 2500000
A35: 발생키 | B35: 발생일자 | C35: 발생 거래처 | D35: 기초금액 | E35: 발생금액 | F35: 회수키 | G35: 회수일자 | H35: 회수 거래처 | I35: 회수금액 | J35: 회수잔액 | K35: 회수기간 | L35: 가중평균 회수금액
A36: 최근 24개월 | B36: 44652
F37: 2 | G37: 44773 | H37: b | I37: 2000000 | J37: =E26-I37 -> 0 | K37: =G37-B26 -> 153 | L37: =K37*I37 -> 306000000
F38: 3 | G38: 44773 | H38: b | I38: 500000 | J38: =E28-I38 -> 2000000 | K38: =G38-B28 -> 123 | L38: =K38*I38 -> 61500000
F39: 3 | G39: 44804 | H39: b | I39: 1000000 | J39: =J38-I39 -> 1000000 | K39: =G39-B28 -> 154 | L39: =K39*I39 -> 154000000
A40: 4 | B40: 44865 | C40: b | E40: 500000
F41: 3 | G41: 44880 | H41: b | I41: 1000000 | J41: =J39-I41+E40 -> 500000 | K41: =G41-B28 -> 230 | L41: =K41*I41 -> 230000000
F42: 4 | G42: 44880 | H42: b | I42: 100000 | J42: =J41-I42 -> 400000 | K42: =G42-B40 -> 15 | L42: =K42*I42 -> 1500000
A44: 5 | B44: 44957 | C44: b | E44: 1000000
F45: 4 | G45: 45031 | H45: b | I45: 400000 | J45: =J42-I45 -> 0 | K45: =G45-B40 -> 166 | L45: =K45*I45 -> 66400000
F46: 5 | G46: 45031 | H46: b | I46: 100000 | J46: =E44-I46 -> 900000 | K46: =G46-B44 -> 74 | L46: =K46*I46 -> 7400000
A47: 6 | B47: 45015 | C47: b | E47: 1500000
A48: 최근12개월 | B48: 45017
F49: 5 | G49: 45169 | H49: b | I49: 500000 | J49: =J46-I49 -> 400000 | K49: =G49-B44 -> 212 | L49: =K49*I49 -> 106000000
F50: 5 | G50: 45230 | H50: b | I50: 400000 | J50: =J49-I50 -> 0 | K50: =G50-B44 -> 273 | L50: =K50*I50 -> 109200000
F51: 6 | G51: 45230 | H51: b | I51: 1100000 | J51: =E47-I51 -> 400000 | K51: =G51-B47 -> 215 | L51: =K51*I51 -> 236500000
A52: 7 | B52: 45322 | C52: b | E52: 3000000
F53: 6 | G53: 45342 | H53: b | I53: 400000 | J53: =J51-I53 -> 0 | K53: =G53-B47 -> 327 | L53: =K53*I53 -> 130800000
F54: 7 | G54: 45342 | H54: b | I54: 2100000 | J54: =E52-I54 -> 900000 | K54: =G54-B52 -> 20 | L54: =K54*I54 -> 42000000
A55: 8 | B55: 45350 | C55: b | E55: 1700000
F56: 7 | G56: 45371 | H56: b | I56: 500000 | J56: =J54-I56 -> 400000 | K56: =G56-B52 -> 49 | L56: =K56*I56 -> 24500000
A57: 기준월 | B57: 45382

Sheet 사업자번호구분기준
A1: 구분 | B1: 내용 | C1: 비고 | E1: 목차
A2: 01~79 | B2: 개인 과세사업자 | C2: 일반,간이 포함
A3: 90~99 | B3: 개인 면세사업자
A4: 89 | B4: 개인으로 보는 단체 중 종교단체
A5: 80 | B5: 개인으로 보는 단체
A6: 81,86,87,88 | B6: 법인(영리)의 본점
A7: 82 | B7: 법인(비영리)의 본지점 | C7: 법인으로보는 단체포함
A8: 83 | B8: 국가, 지방자치단체
A9: 84 | B9: 외국법인의 본지점
A10: 85 | B10: 법인(영리)의 지점

Sheet 회수율 회수기간 산정 기준
G1: `
B2: 구분 | D2: 회수율 | E2: 회수기간
D3: RATE_PAYR | E3: DPAYR
D4: numeric(20,2) | E4: numeric(20,6)
B5: 0 | C5: 분자 | D5: 1000 | E5: 회수금액이 더 큰 경우
C6: 분모 | D6: 1000000000000
C7: 결과 | D7: 0
B8: null | C8: 분자 | D8: 회수 금액이 없음 | E8: 회수 금액이 없음
C9: 분모 | D9: 1000000
C10: 결과
B12: 회수기간 산출 식
B13: 분자 | C13: 가중평균 회수금액
B14: 분모 | C14: 회수금액
